Workbook

Sheet Instructions
A1: CGC Energy Intelligence Copilot - Data Template
A2: Agent-Thon MVP | Data-entry workbook for Sustainability and Facilities
A3: READ ME FIRST - Populate in this order
A4: Order | B4: Sheet | C4: What to do | D4: Priority
A5: 1 | B5: Energy_Data | C5: Enter one row per floor per month using historical floor electricity bills. | D5: MANDATORY
A6: 2 | B6: Floor_Master | C6: Confirm floor names, uses, areas and aggregate employee counts. | D6: MANDATORY
A7: 3 | B7: Emission_Factor | C7: Use only a confirmed and approved factor. | D7: MANDATORY
A8: 4 | B8: Recommendations | C8: Review and approve the recommendation library before agent use. | D8: MANDATORY
A9: 5 | B9: Occupancy | C9: Populate aggregate floor/month occupancy if available. No employee names. | D9: OPTIONAL FOR MVP
A10: 6 | B10: Tariff | C10: Populate if cost calculations or checks are needed. | D10: OPTIONAL
A11: 7 | B11: Employee_Estimate_Input | C11: Use pseudonymous IDs only; allocations are estimates, not metered use. | D11: OPTIONAL
A12: 8 | B12: Data_Issue_Log | C12: Record discrepancies, gaps and resolutions. | D12: AS NEEDED
A14: Simple data-entry rules
A15: • One row per defined record; do not merge cells in data tables.
A16: • Use the first day of the month for monthly dates.
A17: • Keep Building_ID = MCGC and Floor_ID = F01 to F16.
A18: • Imported bill values are green-font linked inputs. Do not guess missing values.
A19: • Employee estimates must use pseudonymous IDs and be labelled ESTIMATED.
A20: • Keep column names unchanged for Power BI, Power Automate and Copilot Studio.
A22: Data classification legend
A23: Measured | B23: Directly recorded from an approved bill, meter or source record.
A24: Calculated | B24: Derived deterministically from approved inputs using a documented formula.
A25: Estimated | B25: An allocation or approximation; not directly metered.
A26: Inferred/Recommendation | B26: A possible explanation or proposed action; not a confirmed cause.

Sheet Energy_Data
A1: Energy Data
A2: One row = one floor + one month. TNB bills populated for Levels 1-16, January-December 2025. Cost_RM uses exact detailed Caj Semasa only.
A3: Record_ID | B3: Building_ID | C3: Month | D3: Floor_ID | E3: Electricity_kWh | F3: Cost_RM | G3: Max_Demand_kW | H3: Meter_Account | I3: Reading_Type | J3: Source_Document | K3: Data_Status | L3: Quality_Status | M3: Notes
A4: 2025-01-F01 | B4: MCGC | C4: 45658 | D4: F01 | E4: 5555 | F4: 3096.57 | G4: 34 | H4: 220285302003 | I4: Actual Bill | J4: Jan 25.pdf | K4: Measured | L4: Validated | M4: Cost_RM uses detailed Caj Semasa only; excludes rounding adjustment.
A5: 2025-02-F01 | B5: MCGC | C5: 45689 | D5: F01 | E5: 5064 | F5: 2821.5 | G5: 31 | H5: 220285302003 | I5: Actual Bill | J5: Feb 25.pdf | K5: Measured | L5: Validated | M5: Cost_RM uses detailed Caj Semasa only.
A6: 2025-03-F01 | B6: MCGC | C6: 45717 | D6: F01 | E6: 6089 | F6: 3444.45 | G6: 34 | H6: 220285302003 | I6: Actual Bill | J6: Mar 25.pdf | K6: Measured | L6: Validated | M6: Cost_RM uses detailed Caj Semasa only.
A7: 2025-04-F01 | B7: MCGC | C7: 45748 | D7: F01 | E7: 6219 | F7: 3518.33 | G7: 33 | H7: 220285302003 | I7: Actual Bill | J7: Apr 25.pdf | K7: Measured | L7: Validated | M7: Cost_RM uses detailed Caj Semasa only; excludes rounding adjustment.
A8: 2025-05-F01 | B8: MCGC | C8: 45778 | D8: F01 | E8: 6443 | F8: 3594.05 | G8: 36 | H8: 220285302003 | I8: Actual Bill | J8: May 25.pdf | K8: Measured | L8: Validated | M8: Cost_RM uses detailed Caj Semasa only.
A9: 2025-06-F01 | B9: MCGC | C9: 45809 | D9: F01 | E9: 5678 | F9: 3120.04 | G9: 31 | H9: 220285302003 | I9: Actual Bill | J9: Jun 25.pdf | K9: Measured | L9: Validated | M9: Cost_RM uses detailed Caj Semasa only; excludes rounding adjustment.
A10: 2025-07-F01 | B10: MCGC | C10: 45839 | D10: F01 | E10: 7009 | F10: 3736.14 | G10: 35 | H10: 220285302003 | I10: Actual Bill | J10: Jul 25.pdf | K10: Measured | L10: Validated | M10: Cost_RM uses detailed Caj Semasa only; excludes rounding adjustment.
A11: 2025-08-F01 | B11: MCGC | C11: 45870 | D11: F01 | E11: 5676 | F11: 3029.18 | G11: 31 | H11: 220285302003 | I11: Actual Bill | J11: Aug 25.pdf | K11: Measured | L11: Validated | M11: Cost_RM uses detailed Caj Semasa only; excludes rounding adjustment.
A12: 2025-09-F01 | B12: MCGC | C12: 45901 | D12: F01 | E12: 5333 | F12: 2867.19 | G12: 35 | H12: 220285302003 | I12: Actual Bill | J12: Sep 25.pdf | K12: Measured | L12: Validated | M12: Cost_RM uses detailed Caj Semasa only; excludes rounding adjustment.
A13: 2025-10-F01 | B13: MCGC | C13: 45931 | D13: F01 | E13: 6050 | F13: 2903.53 | G13: 32 | H13: 220285302003 | I13: Actual Bill | J13: Oct 25.pdf | K13: Measured | L13: Validated | M13: Cost_RM uses detailed Caj Semasa only; excludes rounding adjustment.
A14: 2025-11-F01 | B14: MCGC | C14: 45962 | D14: F01 | E14: 5509 | F14: 2505.04 | G14: 36 | H14: 220285302003 | I14: Actual Bill | J14: Nov 25.pdf | K14: Measured | L14: Validated | M14: Cost_RM uses detailed Caj Semasa only; excludes prior balance and rounding adjustment.
A15: 2025-12-F01 | B15: MCGC | C15: 45992 | D15: F01 | E15: 5303 | F15: 2554.07 | G15: 31 | H15: 220285302003 | I15: Actual Bill | J15: Dec 25.pdf | K15: Measured | L15: Validated | M15: Cost_RM uses detailed Caj Semasa only; includes RM1.94 late-payment surcharge shown in Caj Semasa; excludes rounding adjustment.
... A138: 2025-03-F12 | B138: MCGC | C138: 45717 | D138: F12 | E138: 7344 | F138: 3981.16 | G138: 37 | H138: 220286039404 | I138: Actual Bill | J138: L12 Mar 25.pdf | K138: Measured | L138: Validated | M138: Cost_RM uses exact Caj Semasa only; excludes negative RM0.01 rounding adjustment.
A139: 2025-04-F12 | B139: MCGC | C139: 45748 | D139: F12 | E139: 7731 | F139: 4191.74 | H139: 220286039404 | I139: Estimated Bill | J139: L12 Apr 25.pdf | K139: Estimated | L139: Issue Identified | M139: Estimated reading due to suspected meter fault; meter-section maximum demand unavailable.
A140: 2025-05-F12 | B140: MCGC | C140: 45778 | D140: F12 | E140: 6597 | F140: -632.62 | G140: 38 | H140: 220286039404 | I140: Actual Bill | J140: L12 May 25.pdf | K140: Measured | L140: Validated | M140: 61-day correction bill following meter replacement; reverses prior April estimate. Exact negative Caj Semasa retained.
A141: 2025-06-F12 | B141: MCGC | C141: 45809 | D141: F12 | E141: 7431 | F141: 4028.5 | G141: 37 | H141: 220286039404 | I141: Actual Bill | J141: L12 Jun 25.pdf | K141: Measured | L141: Validated | M141: Cost_RM uses exact Caj Semasa only; excludes prior credit balance.
A142: 2025-07-F12 | B142: MCGC | C142: 45839 | D142: F12 | E142: 9226 | F142: 4770.55 | G142: 37 | H142: 220286039404 | I142: Actual Bill | J142: L12 Jul 25.pdf | K142: Measured | L142: Validated | M142: Cost_RM uses exact Caj Semasa only.
A143: 2025-08-F12 | B143: MCGC | C143: 45870 | D143: F12 | E143: 7724 | F143: 3885.16 | G143: 37 | H143: 220286039404 | I143: Actual Bill | J143: L12 Aug 25.pdf | K143: Measured | L143: Validated | M143: Cost_RM uses exact Caj Semasa only; excludes negative RM0.01 rounding adjustment.
A144: 2025-09-F12 | B144: MCGC | C144: 45901 | D144: F12 | E144: 7110 | F144: 3602.78 | G144: 37 | H144: 220286039404 | I144: Actual Bill | J144: L12 Sep 25.pdf | K144: Measured | L144: Validated | M144: Cost_RM uses exact Caj Semasa only; excludes prior credit balance and RM0.02 rounding adjustment.
A145: 2025-10-F12 | B145: MCGC | C145: 45931 | D145: F12 | E145: 8182 | F145: 3701.15 | G145: 38 | H145: 220286039404 | I145: Actual Bill | J145: L12 Oct 25.pdf | K145: Measured | L145: Validated | M145: Cost_RM uses exact Caj Semasa only; excludes prior balance.
A146: 2025-11-F12 | B146: MCGC | C146: 45962 | D146: F12 | E146: 7038 | F146: 3016.84 | G146: 37 | H146: 220286039404 | I146: Actual Bill | J146: L12 Nov 26.pdf | K146: Measured | L146: Validated | M146: Source filename retained exactly; bill period is November 2025. Cost_RM excludes prior balance.
A147: 2025-12-F12 | B147: MCGC | C147: 45992 | D147: F12 | E147: 7362 | F147: 3340.58 | G147: 36 | H147: 220286039404 | I147: Actual Bill | J147: L12 Dec 25.pdf | K147: Measured | L147: Validated | M147: Cost_RM uses exact Caj Semasa only; includes RM2.46 late-payment surcharge; excludes RM0.02 rounding adjustment.
A148: 2025-01-F13 | B148: MCGC | C148: 45658 | D148: F13 | E148: 6139 | F148: 3325.46 | G148: 38 | H148: 220286027708 | I148: Actual Bill | J148: L13 Jan25.pdf | K148: Measured | L148: Validated | M148: Cost_RM uses exact Caj Semasa only; excludes negative RM0.01 rounding adjustment.
A149: 2025-02-F13 | B149: MCGC | C149: 45689 | D149: F13 | E149: 6501 | F149: 3522.45 | G149: 39 | H149: 220286027708 | I149: Actual Bill | J149: L13 Feb 25.pdf | K149: Measured | L149: Validated | M149: Cost_RM uses exact Caj Semasa only.
A150: 2025-03-F13 | B150: MCGC | C150: 45717 | D150: F13 | E150: 5959 | F150: 3227.51 | G150: 38 | H150: 220286027708 | I150: Actual Bill | J150: L13 Mar 25.pdf | K150: Measured | L150: Validated | M150: Cost_RM uses exact Caj Semasa only; excludes negative RM0.01 rounding adjustment.
A151: 2025-04-F13 | B151: MCGC | C151: 45748 | D151: F13 | E151: 7061 | F151: 3827.17 | G151: 37 | H151: 220286027708 | I151: Actual Bill | J151: L13 Apr 25.pdf | K151: Measured | L151: Validated | M151: Cost_RM uses exact Caj Semasa only; excludes negative RM0.02 rounding adjustment.
... A195: 2025-12-F16 | B195: MCGC | C195: 45992 | D195: F16 | E195: 4529 | F195: 2275.49 | G195: 34 | H195: 220286015304 | I195: Actual Bill | J195: L16 Dec 25.pdf | K195: Measured | L195: Validated | M195: Cost_RM uses exact Caj Semasa only; includes RM1.65 late-payment surcharge and excludes RM0.01 rounding adjustment.
A197: Validation Summary | D197: Annual Level 1 | E197: =SUM(E4:E15) -> 69928 | F197: =SUM(F4:F15) -> 37190.09
D198: Annual Level 2 | E198: =SUM(E16:E27) -> 102371 | F198: =SUM(F16:F27) -> 58385.37
D199: Annual Level 3 | E199: =SUM(E28:E39) -> 102371 | F199: =SUM(F28:F39) -> 58385.37
D200: Annual Level 4 | E200: =SUM(E40:E51) -> 82234 | F200: =SUM(F40:F51) -> 42053.37
D201: Annual Level 5 | E201: =SUM(E52:E63) -> 110866 | F201: =SUM(F52:F63) -> 57893.02
D202: Annual Level 6 | E202: =SUM(E64:E75) -> 48421 | F202: =SUM(F64:F75) -> 26915.67
D203: Annual Level 7 | E203: =SUM(E76:E87) -> 96227 | F203: =SUM(F76:F87) -> 52076.12
D204: Annual Level 8 | E204: =SUM(E88:E99) -> 104167 | F204: =SUM(F88:F99) -> 55641.78
D205: Annual Level 9 | E205: =SUM(E100:E111) -> 111950 | F205: =SUM(F100:F111) -> 65420.97
D206: Annual Level 10 | E206: =SUM(E112:E123) -> 126986 | F206: =SUM(F112:F123) -> 68848.89
...

Sheet Floor_Master
A1: Floor Master
A2: Pre-listed Menara CGC floors. Complete only confirmed information; unknown fields may remain blank.
A3: Floor_ID | B3: Floor_Name | C3: Floor_Use | D3: Area_m2 | E3: Employee_Count | F3: Data_Centre_Flag | G3: Active_From | H3: Active_To | I3: Notes
A4: F01 | B4: Floor 1 | C4: Main Branch | D4: 447.61 | F4: No
A5: F02 | B5: Floor 2 | C5: CGC Digital | D5: 469.81 | F5: No
A6: F03 | B6: Floor 3 | C6: Business Division | D6: 644.1 | F6: No
A7: F04 | B7: Floor 4 | C7: Internal Audit / Data Centre | D7: 644.1 | F7: Yes
A8: F05 | B8: Floor 5 | C8: IT Division | D8: 644.1 | F8: No
A9: F06 | B9: Floor 6 | C9: Board Room | D9: 644.1 | F9: No
A10: F07 | B10: Floor 7 | C10: Multipurpose Hall | D10: 644.1 | F10: No
A11: F08 | B11: Floor 8 | C11: Facilities & Administration / HR | D11: 644.1 | F11: No
A12: F09 | B12: Floor 9 | C12: Credit Division / CSC / SA&SA | D12: 644.1 | F12: No
A13: F10 | B13: Floor 10 | C13: DDD / CIV / RMD / FMR / TRO | D13: 644.1 | F13: No
A14: F11 | B14: Floor 11 | C14: SRD / CLD / BMD / GMR | D14: 644.1 | F14: No
A15: F12 | B15: Floor 12 | C15: Finance Division | D15: 612.32 | F15: No
... A19: F16 | B19: Floor 16 | C19: PCEO Office | D19: 458.01 | F19: No

Sheet Occupancy
A1: Occupancy
A2: Aggregate floor/month information only. Do not enter employee names.
A3: Month | B3: Floor_ID | C3: Employee_Count | D3: Occupant_Days | E3: Working_Days | F3: Data_Owner | G3: Aggregation_Level | H3: Quality_Status | I3: Notes
A4: 46022 | B4: F01 | C4: 20 | F4: Corporate Sustainability | G4: Annual floor average | H4: Validated | I4: 2025 annual average employee count; reference date denotes reporting year, not January-only occupancy.
A5: 45658 | B5: F02 | C5: 21 | F5: Corporate Sustainability | G5: Annual floor average | H5: Validated | I5: 2025 annual average employee count; reference date denotes reporting year, not January-only occupancy.
A6: 45658 | B6: F03 | C6: 20 | F6: Corporate Sustainability | G6: Annual floor average | H6: Validated | I6: 2025 annual average employee count; reference date denotes reporting year, not January-only occupancy.
A7: 45658 | B7: F04 | C7: 9 | F7: Corporate Sustainability | G7: Annual floor average | H7: Validated | I7: 2025 annual average employee count; reference date denotes reporting year, not January-only occupancy.
A8: 45658 | B8: F05 | C8: 45 | F8: Corporate Sustainability | G8: Annual floor average | H8: Validated | I8: 2025 annual average employee count; reference date denotes reporting year, not January-only occupancy.
A9: 45658 | B9: F06 | F9: Corporate Sustainability | G9: Annual floor average | H9: Missing | I9: 2025 average employee count not provided (source showed "-"); retained as blank, not zero.
A10: 45659 | B10: F07 | F10: Corporate Sustainability | G10: Annual floor average | H10: Missing | I10: 2025 average employee count not provided (source showed "-"); retained as blank, not zero.
A11: 45658 | B11: F08 | C11: 21 | F11: Corporate Sustainability | G11: Annual floor average | H11: Validated | I11: 2025 annual average employee count; reference date denotes reporting year, not January-only occupancy.
A12: 45658 | B12: F09 | C12: 36 | F12: Corporate Sustainability | G12: Annual floor average | H12: Validated | I12: 2025 annual average employee count; reference date denotes reporting year, not January-only occupancy.
A13: 45658 | B13: F10 | C13: 38 | F13: Corporate Sustainability | G13: Annual floor average | H13: Validated | I13: 2025 annual average employee count; reference date denotes reporting year, not January-only occupancy.
A14: 45658 | B14: F11 | C14: 33 | F14: Corporate Sustainability | G14: Annual floor average | H14: Validated | I14: 2025 annual average employee count; reference date denotes reporting year, not January-only occupancy.
A15: 45658 | B15: F12 | C15: 19 | F15: Corporate Sustainability | G15: Annual floor average | H15: Validated | I15: 2025 annual average employee count; reference date denotes reporting year, not January-only occupancy.
A16: 45658 | B16: F13 | C16: 16 | F16: Corporate Sustainability | G16: Annual floor average | H16: Validated | I16: 2025 annual average employee count; reference date denotes reporting year, not January-only occupancy.
A17: 45658 | B17: F14 | C17: 8 | F17: Corporate Sustainability | G17: Annual floor average | H17: Validated | I17: 2025 annual average employee count; reference date denotes reporting year, not January-only occupancy.
A18: 45658 | B18: F15 | C18: 8 | F18: Corporate Sustainability | G18: Annual floor average | H18: Validated | I18: 2025 annual average employee count; reference date denotes reporting year, not January-only occupancy.
A19: 45658 | B19: F16 | C19: 4 | F19: Corporate Sustainability | G19: Annual floor average | H19: Validated | I19: 2025 annual average employee count; reference date denotes reporting year, not January-only occupancy.

Sheet Emission_Factor
A1: Emission Factor
A2: Enter only a confirmed, approved factor and retain its source.
A3: Year | B3: Factor_Value | C3: Unit | D3: Jurisdiction | E3: Effective_From | F3: Effective_To | G3: Source | H3: Approval_Status | I3: Notes
A4: 2025 | B4: 0.74 | C4: kgCO2e/kWh | D4: Malaysia | E4: 45658 | F4: 46387 | G4: Suruhanjaya Tenaga | H4: Approved | I4: Existing workbook value; confirm applicability before production use.

Sheet Tariff
A1: Tariff
A2: Building-wide realized blended electricity rate for MCGC. Calculated from all F01-F16 bill records for each tariff period; do not add separate demand or other charges.
A3: Tariff_ID | B3: Effective_From | C3: Effective_To | D3: Energy_Rate_RM_per_kWh | E3: Demand_Rate_RM_per_kW | F3: Other_Charges_RM | G3: Source | H3: Notes
A4: MCGC-2025-H1-BLENDED | B4: 45658 | C4: 45838 | D4: 0.569 | G4: 2025 TNB bills recorded in Energy_Data | H4: Weighted blended rate = aggregate exact Caj Semasa / aggregate kWh for Jan-Jun 2025 across F01-F16. Includes bill-applied ICPT/KWTBB and power-factor effects where applicable; excludes rounding adjustments and prior balances. Not an approved standalone tariff component.
A5: MCGC-2025-H2-BLENDED | B5: 45839 | C5: 46022 | D5: 0.5101 | G5: 2025 TNB bills recorded in Energy_Data | H5: Weighted blended rate = aggregate exact Caj Semasa / aggregate kWh for Jul-Dec 2025 across F01-F16, reflecting the tariff structure effective 1 Jul 2025 and monthly AFA outcomes. Includes bill-applied KWTBB, retail/power-factor effects and retained late-payment surcharges where present. Not an approved standalone tariff component.

Sheet Recommendations
A1: Recommendation Library
A2: CGC audit measures and voluntary employee actions. Review and approve before Copilot use; savings are indicative, not guaranteed.
A3: Recommendation_ID | B3: Source_Type | C3: Audience | D3: Category | E3: Trigger_Condition | F3: Recommended_Action | G3: Estimate_Type | H3: Estimated_kWh_Saving | I3: Saving_Period | J3: Source_Reported_RM_Saving | K3: Source_Reported_CO2e_t | L3: Assumed_Avoided_Watts | M3: Hours_Avoided_Per_Occurrence | N3: Occurrences_Per_Year | O3: Calculation_Basis | P3: Calculated_CO2e_kg | Q3: Calculated_RM_Saving | R3: Evidence_Source | S3: Source_URL_or_Document | T3: Confidence | U3: Owner_Function | V3: Approval_Status | W3: Copilot_Response_Note | X3: Disclaimer
A4: AUD-001 | B4: CGC Energy Audit | C4: Facilities | D4: Air-conditioning | E4: Material after-hours/night/weekend use | F4: Align AHU operating hours with actual occupancy and investigate unnecessary night/weekend operation. | G4: Audit estimate | H4: 70000 | I4: Annual | J4: 34723 | K4: 54.2 | O4: CGC audit reported values shown; treat as opportunity, not realized savings. | P4: =IFERROR(H4*LOOKUP(2,1/(Emission_Factor!$H$4:$H$100="Approved"),Emission_Factor!$B$4:$B$100),"") -> 51800 | Q4: =IFERROR(H4*LOOKUP(2,1/(Tariff!$D$4:$D$100<>""),Tariff!$D$4:$D$100),"") -> 35707 | R4: Energy Audit Findings_July 2026 / Emission Reduction Roadmap Drafting | S4: Energy Audit Findings_July 2026 / Emission Reduction Roadmap Drafting | T4: High | U4: Facilities | V4: Draft | W4: Present as an audit-derived opportunity; do not describe as realized savings. | X4: Subject to technical validation, approval, implementation and measurement & verification.
A5: AUD-002 | B5: CGC Energy Audit | C5: Facilities | D5: Air-conditioning | E5: Overcooling or inefficient AHU supply-air conditions | F5: Optimize AHU supply-air temperature through Facilities controls and engineering validation. | G5: Audit estimate | H5: 36500 | I5: Annual | J5: 18260 | K5: 28.3 | O5: CGC audit reported values shown; treat as opportunity, not realized savings. | P5: =IFERROR(H5*LOOKUP(2,1/(Emission_Factor!$H$4:$H$100="Approved"),Emission_Factor!$B$4:$B$100),"") -> 27010 | Q5: =IFERROR(H5*LOOKUP(2,1/(Tariff!$D$4:$D$100<>""),Tariff!$D$4:$D$100),"") -> 18618.65 | R5: Energy Audit Findings_July 2026 / Emission Reduction Roadmap Drafting | S5: Energy Audit Findings_July 2026 / Emission Reduction Roadmap Drafting | T5: High | U5: Facilities | V5: Draft | W5: Present as an audit-derived opportunity; do not describe as realized savings. | X5: Subject to technical validation, approval, implementation and measurement & verification.
A6: AUD-003 | B6: CGC Energy Audit | C6: Facilities | D6: Air-conditioning | E6: Low chilled-water delta-T or poor cooling efficiency | F6: Investigate and improve chilled-water delta-T performance through Facilities maintenance. | G6: Audit estimate | H6: 56000 | I6: Annual | J6: 27908 | K6: 43.3 | O6: CGC audit reported values shown; treat as opportunity, not realized savings. | P6: =IFERROR(H6*LOOKUP(2,1/(Emission_Factor!$H$4:$H$100="Approved"),Emission_Factor!$B$4:$B$100),"") -> 41440 | Q6: =IFERROR(H6*LOOKUP(2,1/(Tariff!$D$4:$D$100<>""),Tariff!$D$4:$D$100),"") -> 28565.6 | R6: Energy Audit Findings_July 2026 / Emission Reduction Roadmap Drafting | S6: Energy Audit Findings_July 2026 / Emission Reduction Roadmap Drafting | T6: High | U6: Facilities | V6: Draft | W6: Present as an audit-derived opportunity; do not describe as realized savings. | X6: Subject to technical validation, approval, implementation and measurement & verification.
A7: AUD-004 | B7: CGC Energy Audit | C7: Facilities | D7: Air-conditioning | E7: ACPU deterioration or underperformance | F7: Undertake mechanical restoration of ACPUs based on engineering assessment. | G7: Audit estimate | H7: 38082 | I7: Annual | J7: 19041 | K7: 29.5 | O7: CGC audit reported values shown; treat as opportunity, not realized savings. | P7: =IFERROR(H7*LOOKUP(2,1/(Emission_Factor!$H$4:$H$100="Approved"),Emission_Factor!$B$4:$B$100),"") -> 28180.68 | Q7: =IFERROR(H7*LOOKUP(2,1/(Tariff!$D$4:$D$100<>""),Tariff!$D$4:$D$100),"") -> 19425.628 | R7: Energy Audit Findings_July 2026 / Emission Reduction Roadmap Drafting | S7: Energy Audit Findings_July 2026 / Emission Reduction Roadmap Drafting | T7: High | U7: Facilities | V7: Draft | W7: Present as an audit-derived opportunity; do not describe as realized savings. | X7: Subject to technical validation, approval, implementation and measurement & verification.
A8: AUD-005 | B8: CGC Energy Audit | C8: Facilities | D8: Baseload | E8: Night or weekend baseload remains elevated | F8: Run a baseload reduction program and verify safely switchable equipment before shutdown. | G8: Audit estimate | H8: 48000 | I8: Annual | J8: 24161 | K8: 37.2 | O8: CGC audit reported values shown; treat as opportunity, not realized savings. | P8: =IFERROR(H8*LOOKUP(2,1/(Emission_Factor!$H$4:$H$100="Approved"),Emission_Factor!$B$4:$B$100),"") -> 35520 | Q8: =IFERROR(H8*LOOKUP(2,1/(Tariff!$D$4:$D$100<>""),Tariff!$D$4:$D$100),"") -> 24484.8 | R8: Energy Audit Findings_July 2026 / Emission Reduction Roadmap Drafting | S8: Energy Audit Findings_July 2026 / Emission Reduction Roadmap Drafting | T8: High | U8: Facilities | V8: Draft | W8: Present as an audit-derived opportunity; do not describe as realized savings. | X8: Subject to technical validation, approval, implementation and measurement & verification.
A9: AUD-006 | B9: CGC Energy Audit | C9: Sustainability | D9: Energy Management | E9: Monitoring, targets and accountability are limited | F9: Establish an Energy Management System with policy, committee, targets, dashboard and awareness. | G9: Audit estimate | H9: 57500 | I9: Annual | J9: 28750 | K9: 44.5 | O9: CGC audit reported values shown; treat as opportunity, not realized savings. | P9: =IFERROR(H9*LOOKUP(2,1/(Emission_Factor!$H$4:$H$100="Approved"),Emission_Factor!$B$4:$B$100),"") -> 42550 | Q9: =IFERROR(H9*LOOKUP(2,1/(Tariff!$D$4:$D$100<>""),Tariff!$D$4:$D$100),"") -> 29330.75 | R9: Energy Audit Findings_July 2026 / Emission Reduction Roadmap Drafting | S9: Energy Audit Findings_July 2026 / Emission Reduction Roadmap Drafting | T9: High | U9: Sustainability | V9: Draft | W9: Present as an audit-derived opportunity; do not describe as realized savings. | X9: Subject to technical validation, approval, implementation and measurement & verification.
A10: AUD-007 | B10: CGC Energy Audit | C10: Facilities | D10: Power Factor | E10: Average power factor remains below target | F10: Assess power-factor correction; treat benefit primarily as utility-cost reduction. | G10: Audit estimate | I10: Annual | J10: 36000 | O10: CGC audit reported values shown; treat as opportunity, not realized savings. | R10: Energy Audit Findings_July 2026 / Emission Reduction Roadmap Drafting | S10: Energy Audit Findings_July 2026 / Emission Reduction Roadmap Drafting | T10: High | U10: Facilities | V10: Draft | W10: Present as an audit-derived opportunity; do not describe as realized savings. | X10: Subject to technical validation, approval, implementation and measurement & verification.
A11: AUD-008 | B11: CGC Energy Audit | C11: Facilities | D11: Data Centre | E11: Data-center cooling is inefficient | F11: Optimize server-room cooling through Facilities/IT engineering controls. | G11: Audit estimate | H11: 41000 | I11: Annual | J11: 20500 | K11: 31.7 | O11: CGC audit reported values shown; treat as opportunity, not realized savings. | P11: =IFERROR(H11*LOOKUP(2,1/(Emission_Factor!$H$4:$H$100="Approved"),Emission_Factor!$B$4:$B$100),"") -> 30340 | Q11: =IFERROR(H11*LOOKUP(2,1/(Tariff!$D$4:$D$100<>""),Tariff!$D$4:$D$100),"") -> 20914.1 | R11: Energy Audit Findings_July 2026 / Emission Reduction Roadmap Drafting | S11: Energy Audit Findings_July 2026 / Emission Reduction Roadmap Drafting | T11: High | U11: Facilities | V11: Draft | W11: Present as an audit-derived opportunity; do not describe as realized savings. | X11: Subject to technical validation, approval, implementation and measurement & verification.
A12: AUD-009 | B12: CGC Energy Audit | C12: Facilities | D12: Data Centre | E12: PUE and airflow indicate a containment opportunity | F12: Assess cold-aisle containment and airflow management. | G12: Audit estimate | H12: 58100 | I12: Annual | J12: 29050 | K12: 45 | O12: CGC audit reported values shown; treat as opportunity, not realized savings. | P12: =IFERROR(H12*LOOKUP(2,1/(Emission_Factor!$H$4:$H$100="Approved"),Emission_Factor!$B$4:$B$100),"") -> 42994 | Q12: =IFERROR(H12*LOOKUP(2,1/(Tariff!$D$4:$D$100<>""),Tariff!$D$4:$D$100),"") -> 29636.81 | R12: Energy Audit Findings_July 2026 / Emission Reduction Roadmap Drafting | S12: Energy Audit Findings_July 2026 / Emission Reduction Roadmap Drafting | T12: High | U12: Facilities | V12: Draft | W12: Present as an audit-derived opportunity; do not describe as realized savings. | X12: Subject to technical validation, approval, implementation and measurement & verification.
A13: AUD-010 | B13: CGC Energy Audit | C13: Facilities | D13: Lighting | E13: Lighting remains on when areas are unoccupied | F13: Review schedules, manual controls, occupancy sensors and remaining efficient-lighting upgrades. | G13: Not quantified | I13: Annual | O13: CGC audit recommendation; no quantified saving stated. | R13: Energy Audit Findings_July 2026 / Emission Reduction Roadmap Drafting | S13: Energy Audit Findings_July 2026 / Emission Reduction Roadmap Drafting | T13: Medium | U13: Facilities | V13: Draft | W13: Present as an audit-derived opportunity; do not describe as realized savings. | X13: Subject to technical validation, approval, implementation and measurement & verification.
A14: AUD-011 | B14: CGC Energy Audit | C14: Facilities | D14: Demand Management | E14: Simultaneous major-equipment startup contributes to peaks | F14: Stagger major-equipment startup and validate operational constraints. | G14: Not quantified | I14: Annual | O14: CGC audit recommendation; no quantified saving stated. | R14: Energy Audit Findings_July 2026 / Emission Reduction Roadmap Drafting | S14: Energy Audit Findings_July 2026 / Emission Reduction Roadmap Drafting | T14: Medium | U14: Facilities | V14: Draft | W14: Present as an audit-derived opportunity; do not describe as realized savings. | X14: Subject to technical validation, approval, implementation and measurement & verification.
A15: AUD-012 | B15: CGC Energy Audit | C15: Sustainability | D15: Energy Management | E15: Employee energy-saving behavior is not systematic | F15: Run voluntary employee energy-awareness campaigns and team challenges using aggregated results. | G15: Audit estimate | I15: Annual | K15: 12.5 | O15: CGC audit reported values shown; treat as opportunity, not realized savings. | R15: Energy Audit Findings_July 2026 / Emission Reduction Roadmap Drafting | S15: Energy Audit Findings_July 2026 / Emission Reduction Roadmap Drafting | T15: Medium | U15: Sustainability | V15: Draft | W15: Present as an audit-derived opportunity; do not describe as realized savings. | X15: Subject to technical validation, approval, implementation and measurement & verification.
A16: EMP-001 | B16: Employee Behavioral | C16: Employee | D16: Office Equipment | E16: At end of workday | F16: Shut down the monitor and use automatic sleep settings when away. | G16: Scenario estimate | H16: 7.2 | I16: Per person or stated room/action scenario | L16: 15 | M16: 2 | N16: 240 | O16: 15 W x 2 hours x 240 workdays / 1,000. Replace with measured device power. | P16: =IFERROR(H16*LOOKUP(2,1/(Emission_Factor!$H$4:$H$100="Approved"),Emission_Factor!$B$4:$B$100),"") -> 5.328 | Q16: =IFERROR(H16*LOOKUP(2,1/(Tariff!$D$4:$D$100<>""),Tariff!$D$4:$D$100),"") -> 3.67272 | R16: ENERGY STAR - Monitors | S16: https://www.energystar.gov/products/monitors | T16: Medium | U16: Employee | V16: Draft | W16: Offer as a voluntary action and show assumptions used. | X16: Indicative estimate only. Do not use for performance monitoring or claim as measured individual savings.
A17: EMP-002 | B17: Employee Behavioral | C17: Employee | D17: Office Equipment | E17: During lunch or meetings | F17: Put laptop and monitor into sleep mode rather than leaving them active. | G17: Scenario estimate | H17: 4.4 | I17: Per person or stated room/action scenario | L17: 20 | M17: 1 | N17: 220 | O17: 20 W x 1 hour x 220 workdays / 1,000. | P17: =IFERROR(H17*LOOKUP(2,1/(Emission_Factor!$H$4:$H$100="Approved"),Emission_Factor!$B$4:$B$100),"") -> 3.256 | Q17: =IFERROR(H17*LOOKUP(2,1/(Tariff!$D$4:$D$100<>""),Tariff!$D$4:$D$100),"") -> 2.24444 | R17: U.S. Department of Energy - Computers and office equipment | S17: https://www.energy.gov/energysaver/energy-efficient-computers-home-office-equipment-and-electronics | T17: Medium | U17: Employee | V17: Draft | W17: Offer as a voluntary action and show assumptions used. | X17: Indicative estimate only. Do not use for performance monitoring or claim as measured individual savings.
A18: EMP-003 | B18: Employee Behavioral | C18: Employee | D18: Office Equipment | E18: At end of workday | F18: Shut down laptop and approved peripherals instead of leaving them on overnight. | G18: Scenario estimate | H18: 16.8 | I18: Per person or stated room/action scenario | L18: 5 | M18: 14 | N18: 240 | O18: 5 W x 14 after-hours x 240 workdays / 1,000. | P18: =IFERROR(H18*LOOKUP(2,1/(Emission_Factor!$H$4:$H$100="Approved"),Emission_Factor!$B$4:$B$100),"") -> 12.432 | Q18: =IFERROR(H18*LOOKUP(2,1/(Tariff!$D$4:$D$100<>""),Tariff!$D$4:$D$100),"") -> 8.56968 | R18: U.S. Department of Energy - Computers and office equipment | S18: https://www.energy.gov/energysaver/energy-efficient-computers-home-office-equipment-and-electronics | T18: Low | U18: Employee | V18: Draft | W18: Offer as a voluntary action and show assumptions used. | X18: Indicative estimate only. Do not use for performance monitoring or claim as measured individual savings.
A19: EMP-004 | B19: Employee Behavioral | C19: Employee | D19: Meeting Rooms | E19: Leaving a meeting room | F19: Switch off meeting-room lights when empty. | G19: Scenario estimate | H19: 48 | I19: Per person or stated room/action scenario | L19: 100 | M19: 2 | N19: 240 | O19: 100 W x 2 hours x 240 days / 1,000. Replace with actual lighting load. | P19: =IFERROR(H19*LOOKUP(2,1/(Emission_Factor!$H$4:$H$100="Approved"),Emission_Factor!$B$4:$B$100),"") -> 35.52 | Q19: =IFERROR(H19*LOOKUP(2,1/(Tariff!$D$4:$D$100<>""),Tariff!$D$4:$D$100),"") -> 24.4848 | R19: Carbon Trust - Office energy efficiency guides | S19: https://www.carbontrust.com/our-work-and-impact/guides-reports-and-tools/office-energy-efficiency-guides | T19: Medium | U19: Employee | V19: Draft | W19: Offer as a voluntary action and show assumptions used. | X19: Indicative estimate only. Do not use for performance monitoring or claim as measured individual savings.
A20: EMP-005 | B20: Employee Behavioral | C20: Employee | D20: Meeting Rooms | E20: Leaving a meeting room | F20: Switch off display, conferencing equipment and approved peripherals when not required. | G20: Scenario estimate | H20: 48 | I20: Per person or stated room/action scenario | L20: 100 | M20: 2 | N20: 240 | O20: 100 W x 2 hours x 240 days / 1,000. | P20: =IFERROR(H20*LOOKUP(2,1/(Emission_Factor!$H$4:$H$100="Approved"),Emission_Factor!$B$4:$B$100),"") -> 35.52 | Q20: =IFERROR(H20*LOOKUP(2,1/(Tariff!$D$4:$D$100<>""),Tariff!$D$4:$D$100),"") -> 24.4848 | R20: U.S. Department of Energy - Computers and office equipment | S20: https://www.energy.gov/energysaver/energy-efficient-computers-home-office-equipment-and-electronics | T20: Low | U20: Employee | V20: Draft | W20: Offer as a voluntary action and show assumptions used. | X20: Indicative estimate only. Do not use for performance monitoring or claim as measured individual savings.
A21: EMP-006 | B21: Employee Behavioral | C21: Employee | D21: Printing & Paper | E21: Before printing | F21: Use digital review, print only when necessary, and use duplex/default settings. | G21: Qualitative only | I21: Per person or stated room/action scenario | O21: No defensible direct electricity saving assigned; paper reduction is a broader resource benefit. | R21: ENERGY STAR - Imaging equipment | S21: https://www.energystar.gov/products/office_equipment/imaging_equipment | T21: High | U21: Employee | V21: Draft | W21: Offer as a voluntary action and show assumptions used. | X21: Indicative estimate only. Do not use for performance monitoring or claim as measured individual savings.
A22: EMP-007 | B22: Employee Behavioral | C22: Employee | D22: Lift/Stairs | E22: Short trip when physically able and safe | F22: Use stairs voluntarily for a small number of floors. | G22: Qualitative only | I22: Per person or stated room/action scenario | O22: No per-person kWh assigned because marginal lift savings depend on dispatch, occupancy, standby and regeneration. | R22: U.S. General Services Administration - Sustainable facilities resources | S22: https://www.gsa.gov/governmentwide-initiatives/federal-highperformance-green-buildings | T22: Low | U22: Employee | V22: Draft | W22: Offer as a voluntary action and show assumptions used. | X22: Indicative estimate only. Do not use for performance monitoring or claim as measured individual savings.
A23: EMP-008 | B23: Employee Behavioral | C23: Employee | D23: Plug Loads | E23: At end of day | F23: Switch off approved personal fans, lamps and other nonessential plug loads. | G23: Scenario estimate | H23: 19.2 | I23: Per person or stated room/action scenario | L23: 40 | M23: 2 | N23: 240 | O23: 40 W x 2 hours x 240 workdays / 1,000. | P23: =IFERROR(H23*LOOKUP(2,1/(Emission_Factor!$H$4:$H$100="Approved"),Emission_Factor!$B$4:$B$100),"") -> 14.208 | Q23: =IFERROR(H23*LOOKUP(2,1/(Tariff!$D$4:$D$100<>""),Tariff!$D$4:$D$100),"") -> 9.79392 | R23: U.S. Department of Energy - Computers and office equipment | S23: https://www.energy.gov/energysaver/energy-efficient-computers-home-office-equipment-and-electronics | T23: Medium | U23: Employee | V23: Draft | W23: Offer as a voluntary action and show assumptions used. | X23: Indicative estimate only. Do not use for performance monitoring or claim as measured individual savings.
A24: EMP-009 | B24: Employee Behavioral | C24: Employee | D24: Air-conditioning | E24: Workspace feels too cold or warm | F24: Report comfort issues; keep doors/windows closed and avoid personal heaters unless approved. | G24: Scenario estimate | H24: 90 | I24: Per person or stated room/action scenario | L24: 1500 | M24: 1 | N24: 60 | O24: Quantifies avoided 1.5 kW heater for 1 hour on 60 occasions; excludes building HVAC savings. | P24: =IFERROR(H24*LOOKUP(2,1/(Emission_Factor!$H$4:$H$100="Approved"),Emission_Factor!$B$4:$B$100),"") -> 66.6 | Q24: =IFERROR(H24*LOOKUP(2,1/(Tariff!$D$4:$D$100<>""),Tariff!$D$4:$D$100),"") -> 45.909 | R24: Carbon Trust - Office energy efficiency guides | S24: https://www.carbontrust.com/our-work-and-impact/guides-reports-and-tools/office-energy-efficiency-guides | T24: Low | U24: Employee | V24: Draft | W24: Offer as a voluntary action and show assumptions used. | X24: Indicative estimate only. Do not use for performance monitoring or claim as measured individual savings.
A25: EMP-010 | B25: Employee Behavioral | C25: Employee | D25: Lighting | E25: Naturally lit or unoccupied zone | F25: Switch off nonessential lights where controls and safety requirements allow. | G25: Scenario estimate | H25: 19.2 | I25: Per person or stated room/action scenario | L25: 40 | M25: 2 | N25: 240 | O25: 40 W x 2 hours x 240 workdays / 1,000. | P25: =IFERROR(H25*LOOKUP(2,1/(Emission_Factor!$H$4:$H$100="Approved"),Emission_Factor!$B$4:$B$100),"") -> 14.208 | Q25: =IFERROR(H25*LOOKUP(2,1/(Tariff!$D$4:$D$100<>""),Tariff!$D$4:$D$100),"") -> 9.79392 | R25: Carbon Trust - Office energy efficiency guides | S25: https://www.carbontrust.com/our-work-and-impact/guides-reports-and-tools/office-energy-efficiency-guides | T25: Medium | U25: Employee | V25: Draft | W25: Offer as a voluntary action and show assumptions used. | X25: Indicative estimate only. Do not use for performance monitoring or claim as measured individual savings.
A26: EMP-011 | B26: Employee Behavioral | C26: Employee | D26: Workspace Consolidation | E26: Several areas used at low occupancy | F26: Consolidate use into fewer rooms/zones so unused lighting and approved equipment can be off. | G26: Scenario estimate | H26: 50 | I26: Per person or stated room/action scenario | L26: 500 | M26: 2 | N26: 50 | O26: 500 W x 2 hours x 50 occasions / 1,000; HVAC excluded unless zoned control confirmed. | P26: =IFERROR(H26*LOOKUP(2,1/(Emission_Factor!$H$4:$H$100="Approved"),Emission_Factor!$B$4:$B$100),"") -> 37 | Q26: =IFERROR(H26*LOOKUP(2,1/(Tariff!$D$4:$D$100<>""),Tariff!$D$4:$D$100),"") -> 25.505 | R26: Carbon Trust - Office energy efficiency guides | S26: https://www.carbontrust.com/our-work-and-impact/guides-reports-and-tools/office-energy-efficiency-guides | T26: Low | U26: Employee | V26: Draft | W26: Offer as a voluntary action and show assumptions used. | X26: Indicative estimate only. Do not use for performance monitoring or claim as measured individual savings.
A27: EMP-012 | B27: Employee Behavioral | C27: Employee | D27: Meeting Rooms | E27: Selecting a room for a small meeting | F27: Book a right-sized room and release unused bookings. | G27: Scenario estimate | H27: 15 | I27: Per person or stated room/action scenario | L27: 150 | M27: 1 | N27: 100 | O27: 150 W x 1 hour x 100 bookings / 1,000; HVAC excluded. | P27: =IFERROR(H27*LOOKUP(2,1/(Emission_Factor!$H$4:$H$100="Approved"),Emission_Factor!$B$4:$B$100),"") -> 11.1 | Q27: =IFERROR(H27*LOOKUP(2,1/(Tariff!$D$4:$D$100<>""),Tariff!$D$4:$D$100),"") -> 7.6515 | R27: Carbon Trust - Office energy efficiency guides | S27: https://www.carbontrust.com/our-work-and-impact/guides-reports-and-tools/office-energy-efficiency-guides | T27: Low | U27: Employee | V27: Draft | W27: Offer as a voluntary action and show assumptions used. | X27: Indicative estimate only. Do not use for performance monitoring or claim as measured individual savings.
A28: EMP-013 | B28: Employee Behavioral | C28: Employee | D28: Office Equipment | E28: Peripherals remain energized | F28: Use approved switched power strips for nonessential peripherals after work. | G28: Scenario estimate | H28: 10.08 | I28: Per person or stated room/action scenario | L28: 3 | M28: 14 | N28: 240 | O28: 3 W x 14 hours x 240 workdays / 1,000. | P28: =IFERROR(H28*LOOKUP(2,1/(Emission_Factor!$H$4:$H$100="Approved"),Emission_Factor!$B$4:$B$100),"") -> 7.4592 | Q28: =IFERROR(H28*LOOKUP(2,1/(Tariff!$D$4:$D$100<>""),Tariff!$D$4:$D$100),"") -> 5.141808 | R28: U.S. Department of Energy - Computers and office equipment | S28: https://www.energy.gov/energysaver/energy-efficient-computers-home-office-equipment-and-electronics | T28: Low | U28: Employee | V28: Draft | W28: Offer as a voluntary action and show assumptions used. | X28: Indicative estimate only. Do not use for performance monitoring or claim as measured individual savings.
A29: EMP-014 | B29: Employee Behavioral | C29: Employee | D29: Printing & Paper | E29: A document must be printed | F29: Batch print jobs and use shared ENERGY STAR-qualified multifunction equipment. | G29: Qualitative only | I29: Per person or stated room/action scenario | O29: No direct kWh assigned; energy per page depends on model, warm-up cycles and job size. | R29: ENERGY STAR - Imaging equipment | S29: https://www.energystar.gov/products/office_equipment/imaging_equipment | T29: Medium | U29: Employee | V29: Draft | W29: Offer as a voluntary action and show assumptions used. | X29: Indicative estimate only. Do not use for performance monitoring or claim as measured individual savings.

Sheet Employee_Estimate_Input
A1: Employee Estimate Input
A2: IMPORTANT: Outputs are estimated allocations, not individually metered consumption. Use pseudonymous IDs only.
A3: Pseudonymous_Person_ID | B3: Month | C3: Floor_ID | D3: FTE | E3: Attendance_Days | F3: Notes

Sheet Data_Issue_Log
A1: Data Issue Log
A2: Track data gaps, discrepancies, reconciliation items and corrective actions.
A3: Issue_ID | B3: Dataset | C3: Period | D3: Floor_ID | E3: Issue_Type | F3: Severity | G3: Owner_Function | H3: Resolution | I3: Status | J3: Closed_Date | K3: Notes
A4: ISS-F12-2025-04 | B4: Energy_Data | C4: Apr-May 2025 | D4: F12 | E4: Reconciliation Difference | F4: Medium | G4: Facilities | H4: April estimated bill reversed in May after meter replacement; exact billed values retained. | I4: Resolved | J4: 45809 | K4: April demand unavailable; May is a 61-day correction bill.

Sheet Lists
A1: Reading_Type | B1: Data_Status | C1: Quality_Status | D1: Yes_No | E1: Approval_Status | F1: Aggregation_Level | G1: Severity | H1: Issue_Status | I1: Category | J1: Issue_Type | K1: Owner_Function | L1: Floor_ID | M1: Building_ID
A2: Actual Bill | B2: Measured | C2: Not Reviewed | D2: Yes | E2: Draft | F2: Floor-Month | G2: Low | H2: Open | I2: Air-conditioning | J2: Missing Data | K2: Sustainability | L2: F01 | M2: MCGC
A3: Meter Reading | B3: Calculated | C3: Pending Validation | D3: No | E3: Pending Approval | F3: Building-Month | G3: Medium | H3: In Progress | I3: Lighting | J3: Duplicate Record | K3: Facilities | L3: F02
A4: Allocated | B4: Estimated | C4: Validated | E4: Approved | F4: Pseudonymous Person-Month | G4: High | H4: Resolved | I4: Baseload | J4: Outlier | K4: Finance | L4: F03
A5: Estimated | B5: Inferred/Recommendation | C5: Issue Identified | E5: Rejected | G5: Critical | H5: Closed | I5: Data Centre | J5: Reconciliation Difference | K5: HR | L5: F04
A6: Estimated Bill | I6: Occupancy | J6: Invalid Format | K6: IT | L6: F05
I7: Tariff | J7: Unapproved Source | K7: Procurement | L7: F06
I8: Carbon | J8: Other | K8: Other | L8: F07
I9: Other | L9: F08
L10: F09
L11: F10
L12: F11
L13: F12
L14: F13
L15: F14
L16: F15
L17: F16
